<?xml version="1.0" ?>
<!-- =================================================================================== -->
<!-- |    This document was autogenerated by xacro from robot.urdf.xacro               | -->
<!-- |    EDITING THIS FILE BY HAND IS NOT RECOMMENDED                                 | -->
<!-- =================================================================================== -->
<robot name="robot">
  <!-- Specify some standard inertial calculations https://en.wikipedia.org/wiki/List_of_moments_of_inertia -->
  <!-- These make use of xacro's mathematical functionality -->
  <material name="white">
    <color rgba="1 1 1 1"/>
  </material>
  <material name="orange">
    <color rgba="1 0.3 0.1 1"/>
  </material>
  <material name="blue">
    <color rgba="0.2 0.2 1 1"/>
  </material>
  <material name="black">
    <color rgba="0 0 0 1"/>
  </material>
  <material name="red">
    <color rgba="1 0 0 1"/>
  </material>
  <!-- Base Link-->
  <link name="botwheel">
    </link>
  <!-- Chassis Link -->
  <joint name="chassis_joint" type="fixed">
    <parent link="botwheel"/>
    <child link="chassis"/>
    <origin xyz="0.05 0 0"/>
  </joint>
  <link name="chassis">
    <visual>
      <origin xyz="-0.15 0 0.05 "/>
      <geometry>
        <box size="0.3 0.415 0.1"/>
      </geometry>
      <material name="white"/>
    </visual>
    <collision>
      <origin xyz="-0.15 0 0.05 "/>
      <geometry>
        <box size="0.3 0.415 0.1"/>
      </geometry>
    </collision>
    <inertial>
      <origin rpy="0 0 0" xyz="-0.15 0 0.05 "/>
      <mass value="0.7"/>
      <inertia ixx="0.01135895833333333" ixy="0.0" ixz="0.0" iyy="0.006562499999999999" iyz="0.0" izz="0.01529645833333333"/>
    </inertial>
  </link>
  <!-- Left Wheel Link -->
  <joint name="left_wheel_joint" type="continuous">
    <parent link="chassis"/>
    <child link="left_wheel"/>
    <origin rpy="-1.5707963267948966 0 0" xyz="-0.05 0.2425 0"/>
    <axis xyz="0 0 1"/>
  </joint>
  <link name="left_wheel">
    <visual>
      <geometry>
        <cylinder length="0.045" radius="0.08"/>
      </geometry>
      <material name="black"/>
      <origin xyz="0 0 0"/>
    </visual>
    <collision>
      <geometry>
        <cylinder length="0.045" radius="0.08"/>
      </geometry>
    </collision>
    <inertial>
      <origin rpy="0 0 0" xyz="0 0 0"/>
      <mass value="0.15"/>
      <inertia ixx="0.00011375000000000001" ixy="0.0" ixz="0.0" iyy="0.00011375000000000001" iyz="0.0" izz="0.00018750000000000003"/>
    </inertial>
  </link>
  <!-- Right Wheel Link -->
  <joint name="right_wheel_joint" type="continuous">
    <parent link="chassis"/>
    <child link="right_wheel"/>
    <origin rpy="1.5707963267948966 0 0" xyz="-0.05 -0.2425 0"/>
    <axis xyz="0 0 -1"/>
  </joint>
  <link name="right_wheel">
    <visual>
      <geometry>
        <cylinder length="0.045" radius="0.08"/>
      </geometry>
      <material name="black"/>
      <origin xyz="0 0 0"/>
    </visual>
    <collision>
      <geometry>
        <cylinder length="0.045" radius="0.08"/>
      </geometry>
    </collision>
    <inertial>
      <origin rpy="0 0 0" xyz="0 0 0"/>
      <mass value="0.15"/>
      <inertia ixx="0.00011375000000000001" ixy="0.0" ixz="0.0" iyy="0.00011375000000000001" iyz="0.0" izz="0.00018750000000000003"/>
    </inertial>
  </link>
  <!-- Caster Wheel -->
  <joint name="caster_wheel_joint" type="fixed">
    <parent link="chassis"/>
    <child link="caster_wheel"/>
    <origin xyz="-0.3 0 0"/>
  </joint>
  <link name="caster_wheel">
    <visual>
      <geometry>
        <sphere radius="0.08"/>
      </geometry>
      <material name="blue"/>
    </visual>
    <collision>
      <geometry>
        <sphere radius="0.08"/>
      </geometry>
    </collision>
    <inertial>
      <origin rpy="0 0 0" xyz="0 0 0"/>
      <mass value="0.1"/>
      <inertia ixx="0.00010000000000000005" ixy="0.0" ixz="0.0" iyy="0.00010000000000000005" iyz="0.0" izz="0.00010000000000000005"/>
    </inertial>
  </link>
  <gazebo reference="caster_wheel">
    <mu1 value="0.0001"/>
    <mu2 value="0.0001"/>
  </gazebo>
  <joint name="caster_wheel_joint2" type="fixed">
    <parent link="chassis"/>
    <child link="caster_wheel2"/>
    <origin xyz="0.03 0 0"/>
  </joint>
  <link name="caster_wheel2">
    <visual>
      <geometry>
        <sphere radius="0.08"/>
      </geometry>
      <material name="blue"/>
    </visual>
    <collision>
      <geometry>
        <sphere radius="0.08"/>
      </geometry>
    </collision>
    <inertial>
      <origin rpy="0 0 0" xyz="0 0 0"/>
      <mass value="0.1"/>
      <inertia ixx="0.00010000000000000005" ixy="0.0" ixz="0.0" iyy="0.00010000000000000005" iyz="0.0" izz="0.00010000000000000005"/>
    </inertial>
  </link>
  <gazebo reference="caster_wheel2">
    <mu1 value="0.0001"/>
    <mu2 value="0.0001"/>
  </gazebo>
  <gazebo>
    <plugin filename="gz-sim-diff-drive-system" name="gz::sim::systems::DiffDrive">
      <alwaysOn>true</alwaysOn>
      <!-- Wheel info -->
      <left_joint>left_wheel_joint</left_joint>
      <right_joint>right_wheel_joint</right_joint>
      <wheel_separation>0.4850</wheel_separation>
      <wheel_diameter>0.1</wheel_diameter>
      <!-- Limits -->
      <max_wheel_torque>200</max_wheel_torque>
      <max_wheel_acceleration>10.0</max_wheel_acceleration>
      <topic>cmd_vel</topic>
      <!-- Output -->
      <robotBaseFrame>base_link</robotBaseFrame>
      <odom_publish_frequency>1</odom_publish_frequency>
      <publish_odom>true</publish_odom>
      <publish_odom_tf>true</publish_odom_tf>
      <publish_wheel_tf>true</publish_wheel_tf>
    </plugin>
    <!-- Moving Forward-->
    <plugin filename="gz-sim-triggered-publisher-system" name="gz::sim::systems::TriggeredPublisher">
      <input topic="/keyboard/keypress" type="gz.msgs.Int32">
        <match field="data">16777235</match>
      </input>
      <output topic="/cmd_vel" type="gz.msgs.Twist">
            linear: {x: 3}, angular: {z: 0.0}
            </output>
    </plugin>
    <plugin filename="gz-sim-triggered-publisher-system" name="gz::sim::systems::TriggeredPublisher">
      <input topic="/keyboard/keypress" type="gz.msgs.Int32">
        <match field="data">16777237</match>
      </input>
      <output topic="/cmd_vel" type="gz.msgs.Twist">
                linear: {x: -3}, angular: {z: 0.0}
            </output>
    </plugin>
    <plugin filename="gz-sim-triggered-publisher-system" name="gz::sim::systems::TriggeredPublisher">
      <input topic="/keyboard/keypress" type="gz.msgs.Int32">
        <match field="data">16777234</match>
      </input>
      <output topic="/cmd_vel" type="gz.msgs.Twist">
                linear: {x: 0.0}, angular: {z: 5}
            </output>
    </plugin>
    <plugin filename="gz-sim-triggered-publisher-system" name="gz::sim::systems::TriggeredPublisher">
      <input topic="/keyboard/keypress" type="gz.msgs.Int32">
        <match field="data">16777236</match>
      </input>
      <output topic="/cmd_vel" type="gz.msgs.Twist">
                linear: {x: 0.0}, angular: {z: -5}
            </output>
    </plugin>
    <plugin filename="gz-sim-joint-state-publisher-system" name="gz::sim::systems::JointStatePublisher">
        </plugin>
    <plugin filename="gz-sim-pose-publisher-system" name="gz::sim::systems::PosePublisher">
      <!-- <publish_link_pose>true</publish_link_pose> -->
      <!-- <use_pose_vector_msg>true</use_pose_vector_msg> -->
      <static_publisher>true</static_publisher>
      <static_update_frequency>1</static_update_frequency>
    </plugin>
    <plugin filename="gz-sim-odometry-publisher-system" name="gz::sim::systems::OdometryPublisher">
      <odom_frame>odom</odom_frame>
      <robot_base_frame>botwheel</robot_base_frame>
    </plugin>
  </gazebo>
  <joint name="laser_joint" type="fixed">
    <parent link="chassis"/>
    <child link="laser_frame"/>
    <origin rpy="0 0 0" xyz="-0.095 0 0.145"/>
  </joint>
  <link name="laser_frame">
    <visual>
      <geometry>
        <cylinder length="0.045" radius="0.05"/>
      </geometry>
      <material name="red"/>
    </visual>
    <collision>
      <geometry>
        <cylinder length="0.045" radius="0.08"/>
      </geometry>
      f
        
    </collision>
    <inertial>
      <origin rpy="0 0 0" xyz="0 0 0"/>
      <mass value="0.15"/>
      <inertia ixx="0.00011375000000000001" ixy="0.0" ixz="0.0" iyy="0.00011375000000000001" iyz="0.0" izz="0.00018750000000000003"/>
    </inertial>
  </link>
  <gazebo reference="laser_frame">
    <material>Gazebo/Red</material>
    <sensor name="laser" type="gpu_lidar">
      <pose>0 0 0 0 0 0</pose>
      <topic>lidar</topic>
      <visualize>true</visualize>
      <update_rate>10</update_rate>
      <always_on>1</always_on>
      <ray>
        <scan>
          <horizontal>
            <samples>360</samples>
            <resolution>1</resolution>
            <min_angle>-3.14</min_angle>
            <max_angle>3.14</max_angle>
          </horizontal>
        </scan>
        <range>
          <min>0.3</min>
          <max>12</max>
          <resolution>0.01</resolution>
        </range>
      </ray>
      <!-- <plugin name="laser_controller" filename="gz-sim-sensors-system">
                <ros>   
                    <argument>~/out:=scan</argument>
                </ros>
                <output_type>sensor_msgs/LaserScan</output_type>
                <frame_name>laser_frame</frame_name>
            </plugin> -->
    </sensor>
  </gazebo>
  <joint name="camera_joint" type="fixed">
    <parent link="chassis"/>
    <child link="camera_link"/>
    <origin rpy="0 0 0" xyz="0.005 0 0.1"/>
  </joint>
  <link name="camera_link">
    <visual>
      <geometry>
        <box size="0.010 0.03 0.03"/>
      </geometry>
      <material name="red"/>
    </visual>
  </link>
  <joint name="camera_optical_joint" type="fixed">
    <origin rpy="-1.5707963267948966 0 -1.5707963267948966" xyz="0 0 0"/>
    <parent link="camera_link"/>
    <child link="camera_link_optical"/>
  </joint>
  <link name="camera_link_optical"/>
  <gazebo reference="camera_link">
    <material>Gazebo/Red</material>
    <sensor name="rgbd_camera" type="rgbd_camera">
      <pose> 0 0 0 0 0 0 </pose>
      <visualize>true</visualize>
      <update_rate>30</update_rate>
      <enable_metrics>true</enable_metrics>
      <camera>
        <horizontal_fov>1.089</horizontal_fov>
        <image>
          <format>R8G8B8</format>
          <width>640</width>
          <height>480</height>
        </image>
        <clip>
          <near>0.05</near>
          <far>8.0</far>
        </clip>
      </camera>
      <topic>rgbd_camera</topic>
    </sensor>
  </gazebo>
</robot>
